multiprocessing.pool.RemoteTraceback: 
"""
Traceback (most recent call last):
  File "/usr/lib/python3.5/multiprocessing/pool.py", line 119, in worker
    result = (True, func(*args, **kwds))
  File "/usr/lib/python3.5/multiprocessing/pool.py", line 44, in mapstar
    return list(map(*args))
  File "src/model.py", line 1032, in simulationFunc
    delay, visibleNodes, adversarialNodes)
  File "src/model.py", line 645, in __init__
    randum.shuffle(availableNodes)
NameError: name 'randum' is not defined
"""

The above exception was the direct cause of the following exception:

Traceback (most recent call last):
  File "src/model.py", line 1264, in <module>
    result = pool.map(simulationFunc, args)
  File "/usr/lib/python3.5/multiprocessing/pool.py", line 260, in map
    return self._map_async(func, iterable, mapstar, chunksize).get()
  File "/usr/lib/python3.5/multiprocessing/pool.py", line 608, in get
    raise self._value
NameError: name 'randum' is not defined
